#错误和异常
##常见错误
####错误
1. 语法错误
2. 逻辑错误
####异常
1. 程序遇到逻辑或者算法错误
2. 运行过程中计算机错误(内存IO问题)

##异常的处理
####try-except
```python
try:
	pass
except Exception as e:	#错误信息被保存到e中
	raise

try:
	a
except NameError as e:
	print("catch Error", e)

print('exec over')
```
####多个异常捕获
```python
try:
	pass
except Exception1 as e:	#错误信息被保存到e中
	raise
except Exception2 as e:	#错误信息被保存到e中
	raise
except Exception as e:	#错误信息被保存到e中
	raise
```
####else
当没有异常被捕获时被执行
####finally
不论是否捕获异常最后都要执行，一般做清理工作
####结合使用
try-except-else-finally
##with...as语句与上下文管理
```python
with context as var:
	with_suite
```

1. context表达式返回一个对象
2. var用来保存返回的对象，单个值或者元组
3. with_suite使用var变量来对context返回对象进行操作

   ```python
   with open('data.txt') as f:	#文件会自动关闭，但错误并不会被处理
   	for line in f.readlines():
   		print(line)
   ```

可以外部再套try-except处理
####自实现with...as
```python
class MyContex():
	def __init__(self, name):
		self.name = name

	def __enter__(self):
		print("__enter__")
		return self

	def do_self(self):
		print("do_self")

	def __exit__(self, exc_type, exc_value, traceback):
		print('__exit__')
		print("Error:", exc_type, 'info:', exc_value)

if __name__ == '__main__':
	with MyContex('test') as f:
		print(f.name)
		f.do_self()
```

应用场景:
1. 文件操作
2. 进程和线程之间互斥对象，如互斥锁
3. 支持上下文的其他对象
##raise和assert语句
####raise语句主动抛出异常
`raise [exception(args)]`;exception要抛出的异常，args描述异常的的元组   
​	
```python
raise TypeError('test Error')
raise IOError('File Not Exit')
```
####assert断言语句

函数参数检测，重要判断条件断言

>用于检测表达式是否为真，如果为假将引发AssertionError
>`assert expression(args)`; expression判断表达式，args对表达式信息描述

```python
assert 0 	#将引发AssertionError
assert 0 ,'23333'
assert 7 === 6, '错误'
```
##标准异常和自定义异常
```python
class FileError(Exception):
	def __init__(self, value):
		self.value = value

	def __str__(self):
		return self.value
try:
	raise FileError("文件错误")
except FileError as e:
	print(e)
except Exception(e):
	print('没有被捕获的异常')
```


